<?xml version="1.0" ?>
<robot name="robot_rover" xmlns:xacro="http://www.ros.org/wiki/xacro">

<xacro:include filename="$(find robot_rover_description)/urdf/materials.xacro" />
<xacro:include filename="$(find robot_rover_description)/urdf/robot_rover.trans" />
<xacro:include filename="$(find robot_rover_description)/urdf/robot_rover.gazebo" />
<link name="base_link">
  <inertial>
    <origin xyz="-0.00033769329833865616 -2.89241795315588e-17 0.17341859806595633" rpy="0 0 0"/>
    <mass value="157.97514244861068"/>
    <inertia ixx="2.127575" iyy="1.770811" izz="1.993805" ixy="-0.0" iyz="-0.0" ixz="0.011722"/>
  </inertial>
  <visual>
    <origin xyz="0 0 0" rpy="0 0 0"/>
    <geometry>
      <mesh filename="package://robot_rover_description/meshes/base_link.stl" scale="0.001 0.001 0.001"/>
    </geometry>
    <material name="silver"/>
  </visual>
  <collision>
    <origin xyz="0 0 0" rpy="0 0 0"/>
    <geometry>
      <mesh filename="package://robot_rover_description/meshes/base_link.stl" scale="0.001 0.001 0.001"/>
    </geometry>
  </collision>
</link>

<link name="left_1">
  <inertial>
    <origin xyz="-6.938893903907228e-17 -0.015000000000000013 -6.938893903907228e-18" rpy="0 0 0"/>
    <mass value="2.663442251713429"/>
    <inertia ixx="0.002597" iyy="0.004794" izz="0.002597" ixy="0.0" iyz="-0.0" ixz="-0.0"/>
  </inertial>
  <visual>
    <origin xyz="0.055 0.15 -0.06" rpy="0 0 0"/>
    <geometry>
      <mesh filename="package://robot_rover_description/meshes/left_1.stl" scale="0.001 0.001 0.001"/>
    </geometry>
    <material name="silver"/>
  </visual>
  <collision>
    <origin xyz="0.055 0.15 -0.06" rpy="0 0 0"/>
    <geometry>
      <mesh filename="package://robot_rover_description/meshes/left_1.stl" scale="0.001 0.001 0.001"/>
    </geometry>
  </collision>
</link>

<link name="right_1">
  <inertial>
    <origin xyz="-6.938893903907228e-17 0.015000000000000013 -6.938893903907228e-18" rpy="0 0 0"/>
    <mass value="2.663442251713429"/>
    <inertia ixx="0.002597" iyy="0.004794" izz="0.002597" ixy="0.0" iyz="0.0" ixz="-0.0"/>
  </inertial>
  <visual>
    <origin xyz="0.055 -0.15 -0.06" rpy="0 0 0"/>
    <geometry>
      <mesh filename="package://robot_rover_description/meshes/right_1.stl" scale="0.001 0.001 0.001"/>
    </geometry>
    <material name="silver"/>
  </visual>
  <collision>
    <origin xyz="0.055 -0.15 -0.06" rpy="0 0 0"/>
    <geometry>
      <mesh filename="package://robot_rover_description/meshes/right_1.stl" scale="0.001 0.001 0.001"/>
    </geometry>
  </collision>
</link>

<link name="lidar_1">
  <inertial>
    <origin xyz="-6.938893903907228e-17 -2.2155700638222048e-17 0.010000000000000009" rpy="0 0 0"/>
    <mass value="0.6042068071016569"/>
    <inertia ixx="0.000205" iyy="0.000205" izz="0.00037" ixy="0.0" iyz="-0.0" ixz="0.0"/>
  </inertial>
  <visual>
    <origin xyz="0.045 0.0 -0.33" rpy="0 0 0"/>
    <geometry>
      <mesh filename="package://robot_rover_description/meshes/lidar_1.stl" scale="0.001 0.001 0.001"/>
    </geometry>
    <material name="silver"/>
  </visual>
  <collision>
    <origin xyz="0.045 0.0 -0.33" rpy="0 0 0"/>
    <geometry>
      <mesh filename="package://robot_rover_description/meshes/lidar_1.stl" scale="0.001 0.001 0.001"/>
    </geometry>
  </collision>
</link>

<joint name="Revolute 1" type="continuous">
  <origin xyz="-0.055 -0.15 0.06" rpy="0 0 0"/>
  <parent link="base_link"/>
  <child link="left_1"/>
  <axis xyz="0.0 1.0 0.0"/>
</joint>

<joint name="Revolute 2" type="continuous">
  <origin xyz="-0.055 0.15 0.06" rpy="0 0 0"/>
  <parent link="base_link"/>
  <child link="right_1"/>
  <axis xyz="0.0 -1.0 0.0"/>
</joint>

<joint name="Rigid 3" type="fixed">
  <origin xyz="-0.045 0.0 0.33" rpy="0 0 0"/>
  <parent link="base_link"/>
  <child link="lidar_1"/>
</joint>

</robot>
